<?xml version="1.0" ?>
<sdf version='1.7'>
  <world name='default'>
    <light name='sun' type='directional'>
      <cast_shadows>1</cast_shadows>
      <pose>0 0 10 0 -0 0</pose>
      <diffuse>0.8 0.8 0.8 1</diffuse>
      <specular>0.2 0.2 0.2 1</specular>
      <attenuation>
        <range>1000</range>
        <constant>0.9</constant>
        <linear>0.01</linear>
        <quadratic>0.001</quadratic>
      </attenuation>
      <direction>-0.5 0.1 -0.9</direction>
      <spot>
        <inner_angle>0</inner_angle>
        <outer_angle>0</outer_angle>
        <falloff>0</falloff>
      </spot>
    </light>
    <model name='ground_plane'>
      <static>1</static>
      <link name='link'>
        <collision name='collision'>
          <geometry>
            <plane>
              <normal>0 0 1</normal>
              <size>100 100</size>
            </plane>
          </geometry>
          <surface>
            <contact>
              <collide_bitmask>65535</collide_bitmask>
              <ode/>
            </contact>
            <friction>
              <ode>
                <mu>100</mu>
                <mu2>50</mu2>
              </ode>
              <torsional>
                <ode/>
              </torsional>
            </friction>
            <bounce/>
          </surface>
          <max_contacts>10</max_contacts>
        </collision>
        <visual name='visual'>
          <cast_shadows>0</cast_shadows>
          <geometry>
            <plane>
              <normal>0 0 1</normal>
              <size>100 100</size>
            </plane>
          </geometry>
          <material>
            <script>
              <uri>file://media/materials/scripts/gazebo.material</uri>
              <name>Gazebo/Grey</name>
            </script>
          </material>
        </visual>
        <self_collide>0</self_collide>
        <enable_wind>0</enable_wind>
        <kinematic>0</kinematic>
      </link>
    </model>
    <gravity>0 0 -9.8</gravity>
    <magnetic_field>6e-06 2.3e-05 -4.2e-05</magnetic_field>
    <atmosphere type='adiabatic'/>
    <physics type='ode'>
      <max_step_size>0.001</max_step_size>
      <real_time_factor>1</real_time_factor>
      <real_time_update_rate>1000</real_time_update_rate>
    </physics>
    <scene>
      <ambient>0.4 0.4 0.4 1</ambient>
      <background>0.7 0.7 0.7 1</background>
      <shadows>1</shadows>
    </scene>
    <wind/>
    <spherical_coordinates>
      <surface_model>EARTH_WGS84</surface_model>
      <latitude_deg>0</latitude_deg>
      <longitude_deg>0</longitude_deg>
      <elevation>0</elevation>
      <heading_deg>0</heading_deg>
    </spherical_coordinates>
    <model name='leo'>
      <link name='base_footprint'>
        <inertial>
          <pose>-0.019651 0.011678 0.16607 0 -0 0</pose>
          <mass>1.58623</mass>
          <inertia>
            <ixx>0.0104263</ixx>
            <ixy>0.00117621</ixy>
            <ixz>-0.000888068</ixz>
            <iyy>0.0104541</iyy>
            <iyz>0.000219632</iyz>
            <izz>0.0181727</izz>
          </inertia>
        </inertial>
        <collision name='base_footprint_fixed_joint_lump__base_link_collision'>
          <pose>0 0 0.19783 0 -0 0</pose>
          <geometry>
            <mesh>
              <scale>1 1 1</scale>
              <uri>/home/ngocmanh/catkin_ws/src/DrivingCarByHandGestures/my_worlds/models/Chassis_outline.stl</uri>
            </mesh>
          </geometry>
          <max_contacts>10</max_contacts>
          <surface>
            <contact>
              <ode/>
            </contact>
            <bounce/>
            <friction>
              <torsional>
                <ode/>
              </torsional>
              <ode/>
            </friction>
          </surface>
        </collision>
        <collision name='base_footprint_fixed_joint_lump__antenna_link_collision_1'>
          <pose>-0.0052 0.056 0.21933 0 -0 0</pose>
          <geometry>
            <cylinder>
              <length>0.056</length>
              <radius>0.0055</radius>
            </cylinder>
          </geometry>
          <max_contacts>10</max_contacts>
          <surface>
            <contact>
              <ode/>
            </contact>
            <bounce/>
            <friction>
              <torsional>
                <ode/>
              </torsional>
              <ode/>
            </friction>
          </surface>
        </collision>
        <visual name='base_footprint_fixed_joint_lump__base_link_visual'>
          <pose>0 0 0.19783 0 -0 0</pose>
          <geometry>
            <mesh>
              <scale>1 1 1</scale>
              <uri>/home/ngocmanh/catkin_ws/src/DrivingCarByHandGestures/my_worlds/models/Chassis.dae</uri>
            </mesh>
          </geometry>
        </visual>
        <visual name='base_footprint_fixed_joint_lump__antenna_link_visual_1'>
          <pose>-0.0052 0.056 0.19133 0 -0 0</pose>
          <geometry>
            <mesh>
              <scale>1 1 1</scale>
              <uri>/home/ngocmanh/catkin_ws/src/DrivingCarByHandGestures/my_worlds/models/Antenna.dae</uri>
            </mesh>
          </geometry>
        </visual>
        <gravity>1</gravity>
        <velocity_decay/>
        <sensor name='leo_camera' type='camera'>
          <always_on>1</always_on>
          <update_rate>30</update_rate>
          <visualize>0</visualize>
          <camera name='leo_camera'>
            <horizontal_fov>1.9</horizontal_fov>
            <image>
              <width>640</width>
              <height>480</height>
              <format>R8G8B8</format>
            </image>
            <clip>
              <near>0.02</near>
              <far>300</far>
            </clip>
            <noise>
              <type>gaussian</type>
              <mean>0</mean>
              <stddev>0.007</stddev>
            </noise>
            <distortion>
              <k1>-0.279817</k1>
              <k2>0.060321</k2>
              <k3>0.000487</k3>
              <p1>0.00031</p1>
              <p2>0</p2>
              <center>0.5 0.5</center>
            </distortion>
          </camera>
          <plugin name='camera_controller' filename='libgazebo_ros_camera.so'>
            <robotNamespace>/</robotNamespace>
            <cameraName>camera</cameraName>
            <imageTopicName>image_raw</imageTopicName>
            <cameraInfoTopicName>camera_info</cameraInfoTopicName>
            <frameName>camera_optical_frame</frameName>
            <distortionK1>-0.279817</distortionK1>
            <distortionK2>0.060321</distortionK2>
            <distortionK3>0.000487</distortionK3>
            <distortionT1>0.000310</distortionT1>
            <distortionT2>0.000000</distortionT2>
          </plugin>
          <pose>0.0971 0 0.15513 0 0.2094 0</pose>
        </sensor>
        <self_collide>0</self_collide>
        <enable_wind>0</enable_wind>
        <kinematic>0</kinematic>
      </link>
      <joint name='rocker_L_joint' type='revolute'>
        <pose relative_to='base_footprint'>0.00263 0.14167 0.15052 0 -0 3.14159</pose>
        <parent>base_footprint</parent>
        <child>rocker_L_link</child>
        <axis>
          <xyz>0 1 0</xyz>
          <limit>
            <lower>-0.24</lower>
            <upper>0.24</upper>
            <effort>100</effort>
            <velocity>100</velocity>
          </limit>
          <dynamics>
            <damping>0.1</damping>
            <friction>1</friction>
            <spring_reference>0</spring_reference>
            <spring_stiffness>0</spring_stiffness>
          </dynamics>
        </axis>
      </joint>
      <link name='rocker_L_link'>
        <pose relative_to='rocker_L_joint'>0 0 0 0 -0 0</pose>
        <inertial>
          <pose>0 0.01346 -0.06506 0 -0 0</pose>
          <mass>1.38734</mass>
          <inertia>
            <ixx>0.002956</ixx>
            <ixy>-1.48932e-06</ixy>
            <ixz>-8.10341e-06</ixz>
            <iyy>0.02924</iyy>
            <iyz>7.112e-05</iyz>
            <izz>0.02832</izz>
          </inertia>
        </inertial>
        <collision name='rocker_L_link_collision'>
          <pose>0 0 0 0 -0 0</pose>
          <geometry>
            <mesh>
              <scale>1 1 1</scale>
              <uri>/home/ngocmanh/catkin_ws/src/DrivingCarByHandGestures/my_worlds/models/Rocker_outline.stl</uri>
            </mesh>
          </geometry>
          <surface>
            <contact>
              <ode>
                <kp>1e+06</kp>
                <kd>1</kd>
                <min_depth>0.003</min_depth>
              </ode>
            </contact>
            <friction>
              <ode/>
              <torsional>
                <ode/>
              </torsional>
            </friction>
            <bounce/>
          </surface>
          <max_contacts>10</max_contacts>
        </collision>
        <visual name='rocker_L_link_visual'>
          <pose>0 0 0 0 -0 0</pose>
          <geometry>
            <mesh>
              <scale>1 1 1</scale>
              <uri>/home/ngocmanh/catkin_ws/src/DrivingCarByHandGestures/my_worlds/models/Rocker.dae</uri>
            </mesh>
          </geometry>
        </visual>
        <gravity>1</gravity>
        <velocity_decay/>
        <self_collide>0</self_collide>
        <enable_wind>0</enable_wind>
        <kinematic>0</kinematic>
      </link>
      <joint name='wheel_FL_joint' type='revolute'>
        <pose relative_to='rocker_L_link'>-0.15256 -0.08214 -0.08802 0 -0 0</pose>
        <parent>rocker_L_link</parent>
        <child>wheel_FL_link</child>
        <axis>
          <xyz>0 -1 0</xyz>
          <limit>
            <lower>-1e+16</lower>
            <upper>1e+16</upper>
          </limit>
          <dynamics>
            <damping>0.1</damping>
            <friction>0.3125</friction>
            <spring_reference>0</spring_reference>
            <spring_stiffness>0</spring_stiffness>
          </dynamics>
        </axis>
      </joint>
      <link name='wheel_FL_link'>
        <pose relative_to='wheel_FL_joint'>0 0 0 0 -0 0</pose>
        <inertial>
          <pose>0 0.030026 0 0 -0 0</pose>
          <mass>0.283642</mass>
          <inertia>
            <ixx>0.000391</ixx>
            <ixy>1.23962e-06</ixy>
            <ixz>5.52582e-07</ixz>
            <iyy>0.0004716</iyy>
            <iyz>-2.08204e-06</iyz>
            <izz>0.000391</izz>
          </inertia>
        </inertial>
        <collision name='wheel_FL_link_collision'>
          <pose>0 0.04485 0 1.5708 -0 0</pose>
          <geometry>
            <cylinder>
              <length>0.07</length>
              <radius>0.057</radius>
            </cylinder>
          </geometry>
          <surface>
            <contact>
              <ode>
                <kp>1e+06</kp>
                <kd>1</kd>
                <min_depth>0.003</min_depth>
              </ode>
            </contact>
            <friction>
              <ode>
                <mu>3</mu>
                <mu2>0.5</mu2>
                <fdir1>1 0 0</fdir1>
              </ode>
              <torsional>
                <ode/>
              </torsional>
            </friction>
            <bounce/>
          </surface>
          <max_contacts>10</max_contacts>
        </collision>
        <collision name='wheel_FL_link_collision_1'>
          <pose>0 0.04485 0 1.5708 -0 0</pose>
          <geometry>
            <cylinder>
              <length>0.04</length>
              <radius>0.0625</radius>
            </cylinder>
          </geometry>
          <surface>
            <contact>
              <ode>
                <kp>1e+06</kp>
                <kd>1</kd>
                <min_depth>0.003</min_depth>
              </ode>
            </contact>
            <friction>
              <ode>
                <mu>3</mu>
                <mu2>0.5</mu2>
                <fdir1>1 0 0</fdir1>
              </ode>
              <torsional>
                <ode/>
              </torsional>
            </friction>
            <bounce/>
          </surface>
          <max_contacts>10</max_contacts>
        </collision>
        <collision name='wheel_FL_link_collision_2'>
          <pose>0 0 0 0 -0 0</pose>
          <geometry>
            <mesh>
              <scale>1 1 1</scale>
              <uri>/home/ngocmanh/catkin_ws/src/DrivingCarByHandGestures/my_worlds/models/Wheel_outline.stl</uri>
            </mesh>
          </geometry>
          <surface>
            <contact>
              <ode>
                <kp>1e+06</kp>
                <kd>1</kd>
                <min_depth>0.003</min_depth>
              </ode>
            </contact>
            <friction>
              <ode>
                <mu>3</mu>
                <mu2>0.5</mu2>
                <fdir1>1 0 0</fdir1>
              </ode>
              <torsional>
                <ode/>
              </torsional>
            </friction>
            <bounce/>
          </surface>
          <max_contacts>10</max_contacts>
        </collision>
        <visual name='wheel_FL_link_visual'>
          <pose>0 0 0 0 -0 0</pose>
          <geometry>
            <mesh>
              <scale>1 1 1</scale>
              <uri>/home/ngocmanh/catkin_ws/src/DrivingCarByHandGestures/my_worlds/models/WheelA.dae</uri>
            </mesh>
          </geometry>
        </visual>
        <gravity>1</gravity>
        <velocity_decay/>
        <self_collide>0</self_collide>
        <enable_wind>0</enable_wind>
        <kinematic>0</kinematic>
      </link>
      <joint name='wheel_RL_joint' type='revolute'>
        <pose relative_to='rocker_L_link'>0.15256 -0.08214 -0.08802 0 -0 0</pose>
        <parent>rocker_L_link</parent>
        <child>wheel_RL_link</child>
        <axis>
          <xyz>0 -1 0</xyz>
          <limit>
            <lower>-1e+16</lower>
            <upper>1e+16</upper>
          </limit>
          <dynamics>
            <damping>0.1</damping>
            <friction>0.3125</friction>
            <spring_reference>0</spring_reference>
            <spring_stiffness>0</spring_stiffness>
          </dynamics>
        </axis>
      </joint>
      <link name='wheel_RL_link'>
        <pose relative_to='wheel_RL_joint'>0 0 0 0 -0 0</pose>
        <inertial>
          <pose>0 0.030026 0 0 -0 0</pose>
          <mass>0.283642</mass>
          <inertia>
            <ixx>0.000391</ixx>
            <ixy>1.23962e-06</ixy>
            <ixz>5.52582e-07</ixz>
            <iyy>0.0004716</iyy>
            <iyz>-2.08204e-06</iyz>
            <izz>0.000391</izz>
          </inertia>
        </inertial>
        <collision name='wheel_RL_link_collision'>
          <pose>0 0.04485 0 1.5708 -0 0</pose>
          <geometry>
            <cylinder>
              <length>0.07</length>
              <radius>0.057</radius>
            </cylinder>
          </geometry>
          <surface>
            <contact>
              <ode>
                <kp>1e+06</kp>
                <kd>1</kd>
                <min_depth>0.003</min_depth>
              </ode>
            </contact>
            <friction>
              <ode>
                <mu>3</mu>
                <mu2>0.5</mu2>
                <fdir1>1 0 0</fdir1>
              </ode>
              <torsional>
                <ode/>
              </torsional>
            </friction>
            <bounce/>
          </surface>
          <max_contacts>10</max_contacts>
        </collision>
        <collision name='wheel_RL_link_collision_1'>
          <pose>0 0.04485 0 1.5708 -0 0</pose>
          <geometry>
            <cylinder>
              <length>0.04</length>
              <radius>0.0625</radius>
            </cylinder>
          </geometry>
          <surface>
            <contact>
              <ode>
                <kp>1e+06</kp>
                <kd>1</kd>
                <min_depth>0.003</min_depth>
              </ode>
            </contact>
            <friction>
              <ode>
                <mu>3</mu>
                <mu2>0.5</mu2>
                <fdir1>1 0 0</fdir1>
              </ode>
              <torsional>
                <ode/>
              </torsional>
            </friction>
            <bounce/>
          </surface>
          <max_contacts>10</max_contacts>
        </collision>
        <collision name='wheel_RL_link_collision_2'>
          <pose>0 0 0 0 -0 0</pose>
          <geometry>
            <mesh>
              <scale>1 1 1</scale>
              <uri>/home/ngocmanh/catkin_ws/src/DrivingCarByHandGestures/my_worlds/models/Wheel_outline.stl</uri>
            </mesh>
          </geometry>
          <surface>
            <contact>
              <ode>
                <kp>1e+06</kp>
                <kd>1</kd>
                <min_depth>0.003</min_depth>
              </ode>
            </contact>
            <friction>
              <ode>
                <mu>3</mu>
                <mu2>0.5</mu2>
                <fdir1>1 0 0</fdir1>
              </ode>
              <torsional>
                <ode/>
              </torsional>
            </friction>
            <bounce/>
          </surface>
          <max_contacts>10</max_contacts>
        </collision>
        <visual name='wheel_RL_link_visual'>
          <pose>0 0 0 0 -0 0</pose>
          <geometry>
            <mesh>
              <scale>1 1 1</scale>
              <uri>/home/ngocmanh/catkin_ws/src/DrivingCarByHandGestures/my_worlds/models/WheelA.dae</uri>
            </mesh>
          </geometry>
        </visual>
        <gravity>1</gravity>
        <velocity_decay/>
        <self_collide>0</self_collide>
        <enable_wind>0</enable_wind>
        <kinematic>0</kinematic>
      </link>
      <joint name='rocker_R_joint' type='revolute'>
        <pose relative_to='base_footprint'>0.00263 -0.14167 0.15052 0 -0 0</pose>
        <parent>base_footprint</parent>
        <child>rocker_R_link</child>
        <axis>
          <xyz>0 1 0</xyz>
          <limit>
            <lower>-0.24</lower>
            <upper>0.24</upper>
            <effort>100</effort>
            <velocity>100</velocity>
          </limit>
          <dynamics>
            <damping>0.1</damping>
            <friction>1</friction>
            <spring_reference>0</spring_reference>
            <spring_stiffness>0</spring_stiffness>
          </dynamics>
        </axis>
      </joint>
      <link name='rocker_R_link'>
        <pose relative_to='rocker_R_joint'>0 0 0 0 -0 0</pose>
        <inertial>
          <pose>0 0.01346 -0.06506 0 -0 0</pose>
          <mass>1.38734</mass>
          <inertia>
            <ixx>0.002956</ixx>
            <ixy>-1.48932e-06</ixy>
            <ixz>-8.10341e-06</ixz>
            <iyy>0.02924</iyy>
            <iyz>7.112e-05</iyz>
            <izz>0.02832</izz>
          </inertia>
        </inertial>
        <collision name='rocker_R_link_collision'>
          <pose>0 0 0 0 -0 0</pose>
          <geometry>
            <mesh>
              <scale>1 1 1</scale>
              <uri>/home/ngocmanh/catkin_ws/src/DrivingCarByHandGestures/my_worlds/models/Rocker_outline.stl</uri>
            </mesh>
          </geometry>
          <surface>
            <contact>
              <ode>
                <kp>1e+06</kp>
                <kd>1</kd>
                <min_depth>0.003</min_depth>
              </ode>
            </contact>
            <friction>
              <ode/>
              <torsional>
                <ode/>
              </torsional>
            </friction>
            <bounce/>
          </surface>
          <max_contacts>10</max_contacts>
        </collision>
        <visual name='rocker_R_link_visual'>
          <pose>0 0 0 0 -0 0</pose>
          <geometry>
            <mesh>
              <scale>1 1 1</scale>
              <uri>/home/ngocmanh/catkin_ws/src/DrivingCarByHandGestures/my_worlds/models/Rocker.dae</uri>
            </mesh>
          </geometry>
        </visual>
        <gravity>1</gravity>
        <velocity_decay/>
        <self_collide>0</self_collide>
        <enable_wind>0</enable_wind>
        <kinematic>0</kinematic>
      </link>
      <joint name='wheel_FR_joint' type='revolute'>
        <pose relative_to='rocker_R_link'>0.15256 -0.08214 -0.08802 0 -0 0</pose>
        <parent>rocker_R_link</parent>
        <child>wheel_FR_link</child>
        <axis>
          <xyz>0 1 0</xyz>
          <limit>
            <lower>-1e+16</lower>
            <upper>1e+16</upper>
          </limit>
          <dynamics>
            <damping>0.1</damping>
            <friction>0.3125</friction>
            <spring_reference>0</spring_reference>
            <spring_stiffness>0</spring_stiffness>
          </dynamics>
        </axis>
      </joint>
      <link name='wheel_FR_link'>
        <pose relative_to='wheel_FR_joint'>0 0 0 0 -0 0</pose>
        <inertial>
          <pose>0 0.030026 0 0 -0 0</pose>
          <mass>0.283642</mass>
          <inertia>
            <ixx>0.000391</ixx>
            <ixy>1.23962e-06</ixy>
            <ixz>5.52582e-07</ixz>
            <iyy>0.0004716</iyy>
            <iyz>-2.08204e-06</iyz>
            <izz>0.000391</izz>
          </inertia>
        </inertial>
        <collision name='wheel_FR_link_collision'>
          <pose>0 0.04485 0 1.5708 -0 0</pose>
          <geometry>
            <cylinder>
              <length>0.07</length>
              <radius>0.057</radius>
            </cylinder>
          </geometry>
          <surface>
            <contact>
              <ode>
                <kp>1e+06</kp>
                <kd>1</kd>
                <min_depth>0.003</min_depth>
              </ode>
            </contact>
            <friction>
              <ode>
                <mu>3</mu>
                <mu2>0.5</mu2>
                <fdir1>1 0 0</fdir1>
              </ode>
              <torsional>
                <ode/>
              </torsional>
            </friction>
            <bounce/>
          </surface>
          <max_contacts>10</max_contacts>
        </collision>
        <collision name='wheel_FR_link_collision_1'>
          <pose>0 0.04485 0 1.5708 -0 0</pose>
          <geometry>
            <cylinder>
              <length>0.04</length>
              <radius>0.0625</radius>
            </cylinder>
          </geometry>
          <surface>
            <contact>
              <ode>
                <kp>1e+06</kp>
                <kd>1</kd>
                <min_depth>0.003</min_depth>
              </ode>
            </contact>
            <friction>
              <ode>
                <mu>3</mu>
                <mu2>0.5</mu2>
                <fdir1>1 0 0</fdir1>
              </ode>
              <torsional>
                <ode/>
              </torsional>
            </friction>
            <bounce/>
          </surface>
          <max_contacts>10</max_contacts>
        </collision>
        <collision name='wheel_FR_link_collision_2'>
          <pose>0 0 0 0 -0 0</pose>
          <geometry>
            <mesh>
              <scale>1 1 1</scale>
              <uri>/home/ngocmanh/catkin_ws/src/DrivingCarByHandGestures/my_worlds/models/Wheel_outline.stl</uri>
            </mesh>
          </geometry>
          <surface>
            <contact>
              <ode>
                <kp>1e+06</kp>
                <kd>1</kd>
                <min_depth>0.003</min_depth>
              </ode>
            </contact>
            <friction>
              <ode>
                <mu>3</mu>
                <mu2>0.5</mu2>
                <fdir1>1 0 0</fdir1>
              </ode>
              <torsional>
                <ode/>
              </torsional>
            </friction>
            <bounce/>
          </surface>
          <max_contacts>10</max_contacts>
        </collision>
        <visual name='wheel_FR_link_visual'>
          <pose>0 0 0 0 -0 0</pose>
          <geometry>
            <mesh>
              <scale>1 1 1</scale>
              <uri>/home/ngocmanh/catkin_ws/src/DrivingCarByHandGestures/my_worlds/models/WheelB.dae</uri>
            </mesh>
          </geometry>
        </visual>
        <gravity>1</gravity>
        <velocity_decay/>
        <self_collide>0</self_collide>
        <enable_wind>0</enable_wind>
        <kinematic>0</kinematic>
      </link>
      <joint name='wheel_RR_joint' type='revolute'>
        <pose relative_to='rocker_R_link'>-0.15256 -0.08214 -0.08802 0 -0 0</pose>
        <parent>rocker_R_link</parent>
        <child>wheel_RR_link</child>
        <axis>
          <xyz>0 1 0</xyz>
          <limit>
            <lower>-1e+16</lower>
            <upper>1e+16</upper>
          </limit>
          <dynamics>
            <damping>0.1</damping>
            <friction>0.3125</friction>
            <spring_reference>0</spring_reference>
            <spring_stiffness>0</spring_stiffness>
          </dynamics>
        </axis>
      </joint>
      <link name='wheel_RR_link'>
        <pose relative_to='wheel_RR_joint'>0 0 0 0 -0 0</pose>
        <inertial>
          <pose>0 0.030026 0 0 -0 0</pose>
          <mass>0.283642</mass>
          <inertia>
            <ixx>0.000391</ixx>
            <ixy>1.23962e-06</ixy>
            <ixz>5.52582e-07</ixz>
            <iyy>0.0004716</iyy>
            <iyz>-2.08204e-06</iyz>
            <izz>0.000391</izz>
          </inertia>
        </inertial>
        <collision name='wheel_RR_link_collision'>
          <pose>0 0.04485 0 1.5708 -0 0</pose>
          <geometry>
            <cylinder>
              <length>0.07</length>
              <radius>0.057</radius>
            </cylinder>
          </geometry>
          <surface>
            <contact>
              <ode>
                <kp>1e+06</kp>
                <kd>1</kd>
                <min_depth>0.003</min_depth>
              </ode>
            </contact>
            <friction>
              <ode>
                <mu>3</mu>
                <mu2>0.5</mu2>
                <fdir1>1 0 0</fdir1>
              </ode>
              <torsional>
                <ode/>
              </torsional>
            </friction>
            <bounce/>
          </surface>
          <max_contacts>10</max_contacts>
        </collision>
        <collision name='wheel_RR_link_collision_1'>
          <pose>0 0.04485 0 1.5708 -0 0</pose>
          <geometry>
            <cylinder>
              <length>0.04</length>
              <radius>0.0625</radius>
            </cylinder>
          </geometry>
          <surface>
            <contact>
              <ode>
                <kp>1e+06</kp>
                <kd>1</kd>
                <min_depth>0.003</min_depth>
              </ode>
            </contact>
            <friction>
              <ode>
                <mu>3</mu>
                <mu2>0.5</mu2>
                <fdir1>1 0 0</fdir1>
              </ode>
              <torsional>
                <ode/>
              </torsional>
            </friction>
            <bounce/>
          </surface>
          <max_contacts>10</max_contacts>
        </collision>
        <collision name='wheel_RR_link_collision_2'>
          <pose>0 0 0 0 -0 0</pose>
          <geometry>
            <mesh>
              <scale>1 1 1</scale>
              <uri>/home/ngocmanh/catkin_ws/src/DrivingCarByHandGestures/my_worlds/models/Wheel_outline.stl</uri>
            </mesh>
          </geometry>
          <surface>
            <contact>
              <ode>
                <kp>1e+06</kp>
                <kd>1</kd>
                <min_depth>0.003</min_depth>
              </ode>
            </contact>
            <friction>
              <ode>
                <mu>3</mu>
                <mu2>0.5</mu2>
                <fdir1>1 0 0</fdir1>
              </ode>
              <torsional>
                <ode/>
              </torsional>
            </friction>
            <bounce/>
          </surface>
          <max_contacts>10</max_contacts>
        </collision>
        <visual name='wheel_RR_link_visual'>
          <pose>0 0 0 0 -0 0</pose>
          <geometry>
            <mesh>
              <scale>1 1 1</scale>
              <uri>/home/ngocmanh/catkin_ws/src/DrivingCarByHandGestures/my_worlds/models/WheelB.dae</uri>
            </mesh>
          </geometry>
        </visual>
        <gravity>1</gravity>
        <velocity_decay/>
        <self_collide>0</self_collide>
        <enable_wind>0</enable_wind>
        <kinematic>0</kinematic>
      </link>
      <plugin name='rocker_differential' filename='libleo_gazebo_differential_plugin.so'>
        <jointA>rocker_L_joint</jointA>
        <jointB>rocker_R_joint</jointB>
        <forceConstant>100.0</forceConstant>
        <robotNamespace>/</robotNamespace>
      </plugin>
      <static>0</static>
      <plugin name='gazebo_ros_control' filename='libgazebo_ros_control.so'>
        <robotNamespace>/</robotNamespace>
        <robotSimType>gazebo_ros_control/DefaultRobotHWSim</robotSimType>
      </plugin>
      <pose>0 0 1 0 -0 0</pose>
    </model>
    <state world_name='default'>
      <sim_time>292 210000000</sim_time>
      <real_time>398 431404508</real_time>
      <wall_time>1637314896 305497330</wall_time>
      <iterations>292210</iterations>
      <model name='ground_plane'>
        <pose>0 0 0 0 -0 0</pose>
        <scale>1 1 1</scale>
        <link name='link'>
          <pose>0 0 0 0 -0 0</pose>
          <velocity>0 0 0 0 -0 0</velocity>
          <acceleration>0 0 0 0 -0 0</acceleration>
          <wrench>0 0 0 0 -0 0</wrench>
        </link>
      </model>
      <model name='leo'>
        <pose>0.006533 1.7e-05 -0.003008 -1e-06 -0.000654 -0.001658</pose>
        <scale>1 1 1</scale>
        <link name='base_footprint'>
          <pose>0.006533 1.7e-05 -0.003008 -1e-06 -0.000654 -0.001658</pose>
          <velocity>5e-06 0 4e-05 2e-06 4e-06 3e-06</velocity>
          <acceleration>-1e-06 -0 0 -1.5e-05 -0.009593 0.004028</acceleration>
          <wrench>-1e-06 -0 0 0 -0 0</wrench>
        </link>
        <link name='rocker_L_link'>
          <pose>0.009299 0.141682 0.147513 1e-06 4e-06 3.13993</pose>
          <velocity>5e-06 -0 4e-05 2e-06 2e-06 3e-06</velocity>
          <acceleration>-1e-06 0 0 0.257811 -0.000781 -0.087584</acceleration>
          <wrench>-1e-06 0 0 0 -0 0</wrench>
        </link>
        <link name='rocker_R_link'>
          <pose>0.008829 -0.141657 0.147513 -1e-06 0 -0.001658</pose>
          <velocity>6e-06 -0 3.9e-05 2e-06 2e-06 4e-06</velocity>
          <acceleration>-1e-06 -0 -0 0.238873 -0.000329 7.6e-05</acceleration>
          <wrench>-1e-06 -0 -0 0 -0 0</wrench>
        </link>
        <link name='wheel_FL_link'>
          <pose>0.161996 0.223569 0.059494 4e-06 -0.109899 3.13993</pose>
          <velocity>6e-06 0 3.9e-05 -4e-06 3e-05 4e-06</velocity>
          <acceleration>-1e-06 0 -0 -0.6431 0.068473 -0.76909</acceleration>
          <wrench>-0 0 -0 0 -0 0</wrench>
        </link>
        <link name='wheel_FR_link'>
          <pose>0.161253 -0.22405 0.059493 -3e-06 0.099881 -0.001658</pose>
          <velocity>7e-06 0 3.9e-05 -7e-06 4.8e-05 2e-06</velocity>
          <acceleration>-1e-06 0 -0 0.130043 0.006177 0.18607</acceleration>
          <wrench>-0 0 -0 0 -0 0</wrench>
        </link>
        <link name='wheel_RL_link'>
          <pose>-0.143124 0.224076 0.059492 2e-06 -0.105136 3.13993</pose>
          <velocity>6e-06 -0 4.1e-05 7e-06 2.9e-05 4e-06</velocity>
          <acceleration>-1e-06 -0 0 -0.612622 0.067069 -0.62057</acceleration>
          <wrench>-0 -0 0 0 -0 0</wrench>
        </link>
        <link name='wheel_RR_link'>
          <pose>-0.143867 -0.223544 0.059494 -1e-06 0.100735 -0.001658</pose>
          <velocity>7e-06 -1e-06 3.9e-05 9e-06 4.6e-05 1e-06</velocity>
          <acceleration>-1e-06 -0 0 0.136321 0.006303 0.191659</acceleration>
          <wrench>-0 -0 0 0 -0 0</wrench>
        </link>
      </model>
      <light name='sun'>
        <pose>0 0 10 0 -0 0</pose>
      </light>
    </state>
    <gui fullscreen='0'>
      <camera name='user_camera'>
        <pose>4.95942 -5.06622 1.93589 0 0.275643 2.35619</pose>
        <view_controller>orbit</view_controller>
        <projection_type>perspective</projection_type>
      </camera>
    </gui>
  </world>
</sdf>
